{"class":14,"code":"EREQUEST","level":"error","lineNumber":2,"message":"Error transfiriendo datos: Violation of PRIMARY KEY constraint 'PK_implt_client'. Cannot insert duplicate key in object 'telynet.implt_client'. The duplicate key value is (C001).","name":"RequestError","number":2627,"originalError":{"info":{"class":14,"handlerName":"onErrorMessage","lineNumber":2,"message":"Violation of PRIMARY KEY constraint 'PK_implt_client'. Cannot insert duplicate key in object 'telynet.implt_client'. The duplicate key value is (C001).","name":"ERROR","number":2627,"procName":"","serverName":"ciguadr","state":1}},"precedingErrors":[],"procName":"","serverName":"ciguadr","stack":"RequestError: Violation of PRIMARY KEY constraint 'PK_implt_client'. Cannot insert duplicate key in object 'telynet.implt_client'. The duplicate key value is (C001).\n    at handleError (C:\\proyectos\\app\\core_app\\server\\node_modules\\mssql\\lib\\tedious\\request.js:384:15)\n    at Connection.emit (node:events:517:28)\n    at Connection.emit (C:\\proyectos\\app\\core_app\\server\\node_modules\\tedious\\lib\\connection.js:1040:18)\n    at RequestTokenHandler.onErrorMessage (C:\\proyectos\\app\\core_app\\server\\node_modules\\tedious\\lib\\token\\handler.js:365:21)\n    at Readable.<anonymous> (C:\\proyectos\\app\\core_app\\server\\node_modules\\tedious\\lib\\token\\token-stream-parser.js:26:33)\n    at Readable.emit (node:events:517:28)\n    at addChunk (node:internal/streams/readable:368:12)\n    at readableAddChunk (node:internal/streams/readable:341:9)\n    at Readable.push (node:internal/streams/readable:278:10)\n    at next (node:internal/streams/from:98:31)","state":1,"timestamp":"2025-01-18T20:37:00.976Z"}
{"code":"ETIMEOUT","level":"error","message":"Error transfiriendo datos: Timeout: Request failed to complete in 15000ms","name":"RequestError","number":"ETIMEOUT","originalError":{"code":"ETIMEOUT"},"precedingErrors":[],"stack":"RequestError: Timeout: Request failed to complete in 15000ms\n    at C:\\proyectos\\app\\core_app\\server\\node_modules\\mssql\\lib\\tedious\\request.js:449:19\n    at Array.forEach (<anonymous>)\n    at Request.userCallback (C:\\proyectos\\app\\core_app\\server\\node_modules\\mssql\\lib\\tedious\\request.js:446:46)\n    at Request.callback (C:\\proyectos\\app\\core_app\\server\\node_modules\\tedious\\lib\\request.js:205:14)\n    at C:\\proyectos\\app\\core_app\\server\\node_modules\\tedious\\lib\\connection.js:2866:24\n    at process.processTicksAndRejections (node:internal/process/task_queues:95:5)","timestamp":"2025-01-18T20:38:15.727Z"}
{"code":"ETIMEOUT","level":"error","message":"Error transfiriendo datos: Timeout: Request failed to complete in 15000ms","name":"RequestError","number":"ETIMEOUT","originalError":{"code":"ETIMEOUT"},"precedingErrors":[],"stack":"RequestError: Timeout: Request failed to complete in 15000ms\n    at C:\\proyectos\\app\\core_app\\server\\node_modules\\mssql\\lib\\tedious\\request.js:449:19\n    at Array.forEach (<anonymous>)\n    at Request.userCallback (C:\\proyectos\\app\\core_app\\server\\node_modules\\mssql\\lib\\tedious\\request.js:446:46)\n    at Request.callback (C:\\proyectos\\app\\core_app\\server\\node_modules\\tedious\\lib\\request.js:205:14)\n    at C:\\proyectos\\app\\core_app\\server\\node_modules\\tedious\\lib\\connection.js:2866:24\n    at process.processTicksAndRejections (node:internal/process/task_queues:95:5)","timestamp":"2025-01-18T20:40:15.760Z"}
{"code":"ETIMEOUT","level":"error","message":"Error transfiriendo datos: Timeout: Request failed to complete in 15000ms","name":"RequestError","number":"ETIMEOUT","originalError":{"code":"ETIMEOUT"},"precedingErrors":[],"stack":"RequestError: Timeout: Request failed to complete in 15000ms\n    at C:\\proyectos\\app\\core_app\\server\\node_modules\\mssql\\lib\\tedious\\request.js:449:19\n    at Array.forEach (<anonymous>)\n    at Request.userCallback (C:\\proyectos\\app\\core_app\\server\\node_modules\\mssql\\lib\\tedious\\request.js:446:46)\n    at Request.callback (C:\\proyectos\\app\\core_app\\server\\node_modules\\tedious\\lib\\request.js:205:14)\n    at C:\\proyectos\\app\\core_app\\server\\node_modules\\tedious\\lib\\connection.js:2866:24\n    at process.processTicksAndRejections (node:internal/process/task_queues:95:5)","timestamp":"2025-01-18T20:41:15.149Z"}
{"code":"ETIMEOUT","level":"error","message":"Error transfiriendo datos: Timeout: Request failed to complete in 15000ms","name":"RequestError","number":"ETIMEOUT","originalError":{"code":"ETIMEOUT"},"precedingErrors":[],"stack":"RequestError: Timeout: Request failed to complete in 15000ms\n    at C:\\proyectos\\app\\core_app\\server\\node_modules\\mssql\\lib\\tedious\\request.js:449:19\n    at Array.forEach (<anonymous>)\n    at Request.userCallback (C:\\proyectos\\app\\core_app\\server\\node_modules\\mssql\\lib\\tedious\\request.js:446:46)\n    at Request.callback (C:\\proyectos\\app\\core_app\\server\\node_modules\\tedious\\lib\\request.js:205:14)\n    at C:\\proyectos\\app\\core_app\\server\\node_modules\\tedious\\lib\\connection.js:2866:24\n    at process.processTicksAndRejections (node:internal/process/task_queues:95:5)","timestamp":"2025-01-18T20:42:15.604Z"}
{"code":"ETIMEOUT","level":"error","message":"Error transfiriendo datos: Timeout: Request failed to complete in 15000ms","name":"RequestError","number":"ETIMEOUT","originalError":{"code":"ETIMEOUT"},"precedingErrors":[],"stack":"RequestError: Timeout: Request failed to complete in 15000ms\n    at C:\\proyectos\\app\\core_app\\server\\node_modules\\mssql\\lib\\tedious\\request.js:449:19\n    at Array.forEach (<anonymous>)\n    at Request.userCallback (C:\\proyectos\\app\\core_app\\server\\node_modules\\mssql\\lib\\tedious\\request.js:446:46)\n    at Request.callback (C:\\proyectos\\app\\core_app\\server\\node_modules\\tedious\\lib\\request.js:205:14)\n    at C:\\proyectos\\app\\core_app\\server\\node_modules\\tedious\\lib\\connection.js:2866:24\n    at process.processTicksAndRejections (node:internal/process/task_queues:95:5)","timestamp":"2025-01-18T20:43:15.124Z"}
{"code":"ETIMEOUT","level":"error","message":"Error transfiriendo datos: Timeout: Request failed to complete in 15000ms","name":"RequestError","number":"ETIMEOUT","originalError":{"code":"ETIMEOUT"},"precedingErrors":[],"stack":"RequestError: Timeout: Request failed to complete in 15000ms\n    at C:\\proyectos\\app\\core_app\\server\\node_modules\\mssql\\lib\\tedious\\request.js:449:19\n    at Array.forEach (<anonymous>)\n    at Request.userCallback (C:\\proyectos\\app\\core_app\\server\\node_modules\\mssql\\lib\\tedious\\request.js:446:46)\n    at Request.callback (C:\\proyectos\\app\\core_app\\server\\node_modules\\tedious\\lib\\request.js:205:14)\n    at C:\\proyectos\\app\\core_app\\server\\node_modules\\tedious\\lib\\connection.js:2866:24\n    at process.processTicksAndRejections (node:internal/process/task_queues:95:5)","timestamp":"2025-01-18T20:44:15.648Z"}
{"code":"ETIMEOUT","level":"error","message":"Error transfiriendo datos: Timeout: Request failed to complete in 15000ms","name":"RequestError","number":"ETIMEOUT","originalError":{"code":"ETIMEOUT"},"precedingErrors":[],"stack":"RequestError: Timeout: Request failed to complete in 15000ms\n    at C:\\proyectos\\app\\core_app\\server\\node_modules\\mssql\\lib\\tedious\\request.js:449:19\n    at Array.forEach (<anonymous>)\n    at Request.userCallback (C:\\proyectos\\app\\core_app\\server\\node_modules\\mssql\\lib\\tedious\\request.js:446:46)\n    at Request.callback (C:\\proyectos\\app\\core_app\\server\\node_modules\\tedious\\lib\\request.js:205:14)\n    at C:\\proyectos\\app\\core_app\\server\\node_modules\\tedious\\lib\\connection.js:2866:24\n    at process.processTicksAndRejections (node:internal/process/task_queues:95:5)","timestamp":"2025-01-18T20:45:15.257Z"}
{"code":"ETIMEOUT","level":"error","message":"Error transfiriendo datos: Timeout: Request failed to complete in 15000ms","name":"RequestError","number":"ETIMEOUT","originalError":{"code":"ETIMEOUT"},"precedingErrors":[],"stack":"RequestError: Timeout: Request failed to complete in 15000ms\n    at C:\\proyectos\\app\\core_app\\server\\node_modules\\mssql\\lib\\tedious\\request.js:449:19\n    at Array.forEach (<anonymous>)\n    at Request.userCallback (C:\\proyectos\\app\\core_app\\server\\node_modules\\mssql\\lib\\tedious\\request.js:446:46)\n    at Request.callback (C:\\proyectos\\app\\core_app\\server\\node_modules\\tedious\\lib\\request.js:205:14)\n    at C:\\proyectos\\app\\core_app\\server\\node_modules\\tedious\\lib\\connection.js:2866:24\n    at process.processTicksAndRejections (node:internal/process/task_queues:95:5)","timestamp":"2025-01-18T20:46:15.856Z"}
{"code":"ETIMEOUT","level":"error","message":"Error transfiriendo datos: Timeout: Request failed to complete in 15000ms","name":"RequestError","number":"ETIMEOUT","originalError":{"code":"ETIMEOUT"},"precedingErrors":[],"stack":"RequestError: Timeout: Request failed to complete in 15000ms\n    at C:\\proyectos\\app\\core_app\\server\\node_modules\\mssql\\lib\\tedious\\request.js:449:19\n    at Array.forEach (<anonymous>)\n    at Request.userCallback (C:\\proyectos\\app\\core_app\\server\\node_modules\\mssql\\lib\\tedious\\request.js:446:46)\n    at Request.callback (C:\\proyectos\\app\\core_app\\server\\node_modules\\tedious\\lib\\request.js:205:14)\n    at C:\\proyectos\\app\\core_app\\server\\node_modules\\tedious\\lib\\connection.js:2866:24\n    at process.processTicksAndRejections (node:internal/process/task_queues:95:5)","timestamp":"2025-01-18T20:47:15.338Z"}
{"level":"error","message":"Error transfiriendo datos: operation timed out for an unknown reason","stack":"Error: operation timed out for an unknown reason\n    at C:\\proyectos\\app\\core_app\\server\\node_modules\\tarn\\dist\\PendingOperation.js:17:27","timestamp":"2025-01-18T20:48:30.848Z"}
{"level":"error","message":"Error transfiriendo datos: operation timed out for an unknown reason","stack":"Error: operation timed out for an unknown reason\n    at C:\\proyectos\\app\\core_app\\server\\node_modules\\tarn\\dist\\PendingOperation.js:17:27","timestamp":"2025-01-18T20:49:30.351Z"}
{"level":"error","message":"Error transfiriendo datos: operation timed out for an unknown reason","stack":"Error: operation timed out for an unknown reason\n    at C:\\proyectos\\app\\core_app\\server\\node_modules\\tarn\\dist\\PendingOperation.js:17:27","timestamp":"2025-01-18T20:50:30.943Z"}
{"level":"error","message":"Error transfiriendo datos: operation timed out for an unknown reason","stack":"Error: operation timed out for an unknown reason\n    at C:\\proyectos\\app\\core_app\\server\\node_modules\\tarn\\dist\\PendingOperation.js:17:27","timestamp":"2025-01-18T20:51:30.535Z"}
{"level":"error","message":"Error transfiriendo datos: operation timed out for an unknown reason","stack":"Error: operation timed out for an unknown reason\n    at C:\\proyectos\\app\\core_app\\server\\node_modules\\tarn\\dist\\PendingOperation.js:17:27","timestamp":"2025-01-18T20:52:31.027Z"}
{"level":"error","message":"Error transfiriendo datos: operation timed out for an unknown reason","stack":"Error: operation timed out for an unknown reason\n    at C:\\proyectos\\app\\core_app\\server\\node_modules\\tarn\\dist\\PendingOperation.js:17:27","timestamp":"2025-01-18T20:53:30.584Z"}
{"level":"error","message":"Error transfiriendo datos: operation timed out for an unknown reason","stack":"Error: operation timed out for an unknown reason\n    at C:\\proyectos\\app\\core_app\\server\\node_modules\\tarn\\dist\\PendingOperation.js:17:27","timestamp":"2025-01-18T20:54:30.121Z"}
{"level":"error","message":"Error transfiriendo datos: operation timed out for an unknown reason","stack":"Error: operation timed out for an unknown reason\n    at C:\\proyectos\\app\\core_app\\server\\node_modules\\tarn\\dist\\PendingOperation.js:17:27","timestamp":"2025-01-18T20:55:30.708Z"}
{"class":14,"code":"EREQUEST","level":"error","lineNumber":2,"message":"Error transfiriendo datos: Violation of PRIMARY KEY constraint 'PK_implt_client'. Cannot insert duplicate key in object 'telynet.implt_client'. The duplicate key value is (C001).","name":"RequestError","number":2627,"originalError":{"info":{"class":14,"handlerName":"onErrorMessage","lineNumber":2,"message":"Violation of PRIMARY KEY constraint 'PK_implt_client'. Cannot insert duplicate key in object 'telynet.implt_client'. The duplicate key value is (C001).","name":"ERROR","number":2627,"procName":"","serverName":"ciguadr","state":1}},"precedingErrors":[],"procName":"","serverName":"ciguadr","stack":"RequestError: Violation of PRIMARY KEY constraint 'PK_implt_client'. Cannot insert duplicate key in object 'telynet.implt_client'. The duplicate key value is (C001).\n    at handleError (C:\\proyectos\\app\\core_app\\server\\node_modules\\mssql\\lib\\tedious\\request.js:384:15)\n    at Connection.emit (node:events:517:28)\n    at Connection.emit (C:\\proyectos\\app\\core_app\\server\\node_modules\\tedious\\lib\\connection.js:1040:18)\n    at RequestTokenHandler.onErrorMessage (C:\\proyectos\\app\\core_app\\server\\node_modules\\tedious\\lib\\token\\handler.js:365:21)\n    at Readable.<anonymous> (C:\\proyectos\\app\\core_app\\server\\node_modules\\tedious\\lib\\token\\token-stream-parser.js:26:33)\n    at Readable.emit (node:events:517:28)\n    at addChunk (node:internal/streams/readable:368:12)\n    at readableAddChunk (node:internal/streams/readable:341:9)\n    at Readable.push (node:internal/streams/readable:278:10)\n    at next (node:internal/streams/from:98:31)","state":1,"timestamp":"2025-01-18T20:57:00.239Z"}
{"class":14,"code":"EREQUEST","level":"error","lineNumber":2,"message":"Error transfiriendo datos: Violation of PRIMARY KEY constraint 'PK_implt_client'. Cannot insert duplicate key in object 'telynet.implt_client'. The duplicate key value is (C001).","name":"RequestError","number":2627,"originalError":{"info":{"class":14,"handlerName":"onErrorMessage","lineNumber":2,"message":"Violation of PRIMARY KEY constraint 'PK_implt_client'. Cannot insert duplicate key in object 'telynet.implt_client'. The duplicate key value is (C001).","name":"ERROR","number":2627,"procName":"","serverName":"ciguadr","state":1}},"precedingErrors":[],"procName":"","serverName":"ciguadr","stack":"RequestError: Violation of PRIMARY KEY constraint 'PK_implt_client'. Cannot insert duplicate key in object 'telynet.implt_client'. The duplicate key value is (C001).\n    at handleError (C:\\proyectos\\app\\core_app\\server\\node_modules\\mssql\\lib\\tedious\\request.js:384:15)\n    at Connection.emit (node:events:517:28)\n    at Connection.emit (C:\\proyectos\\app\\core_app\\server\\node_modules\\tedious\\lib\\connection.js:1040:18)\n    at RequestTokenHandler.onErrorMessage (C:\\proyectos\\app\\core_app\\server\\node_modules\\tedious\\lib\\token\\handler.js:365:21)\n    at Readable.<anonymous> (C:\\proyectos\\app\\core_app\\server\\node_modules\\tedious\\lib\\token\\token-stream-parser.js:26:33)\n    at Readable.emit (node:events:517:28)\n    at addChunk (node:internal/streams/readable:368:12)\n    at readableAddChunk (node:internal/streams/readable:341:9)\n    at Readable.push (node:internal/streams/readable:278:10)\n    at next (node:internal/streams/from:98:31)","state":1,"timestamp":"2025-01-18T20:58:00.416Z"}
{"class":14,"code":"EREQUEST","level":"error","lineNumber":2,"message":"Error transfiriendo datos: Violation of PRIMARY KEY constraint 'PK_implt_client'. Cannot insert duplicate key in object 'telynet.implt_client'. The duplicate key value is (C001).","name":"RequestError","number":2627,"originalError":{"info":{"class":14,"handlerName":"onErrorMessage","lineNumber":2,"message":"Violation of PRIMARY KEY constraint 'PK_implt_client'. Cannot insert duplicate key in object 'telynet.implt_client'. The duplicate key value is (C001).","name":"ERROR","number":2627,"procName":"","serverName":"ciguadr","state":1}},"precedingErrors":[],"procName":"","serverName":"ciguadr","stack":"RequestError: Violation of PRIMARY KEY constraint 'PK_implt_client'. Cannot insert duplicate key in object 'telynet.implt_client'. The duplicate key value is (C001).\n    at handleError (C:\\proyectos\\app\\core_app\\server\\node_modules\\mssql\\lib\\tedious\\request.js:384:15)\n    at Connection.emit (node:events:517:28)\n    at Connection.emit (C:\\proyectos\\app\\core_app\\server\\node_modules\\tedious\\lib\\connection.js:1040:18)\n    at RequestTokenHandler.onErrorMessage (C:\\proyectos\\app\\core_app\\server\\node_modules\\tedious\\lib\\token\\handler.js:365:21)\n    at Readable.<anonymous> (C:\\proyectos\\app\\core_app\\server\\node_modules\\tedious\\lib\\token\\token-stream-parser.js:26:33)\n    at Readable.emit (node:events:517:28)\n    at addChunk (node:internal/streams/readable:368:12)\n    at readableAddChunk (node:internal/streams/readable:341:9)\n    at Readable.push (node:internal/streams/readable:278:10)\n    at next (node:internal/streams/from:98:31)","state":1,"timestamp":"2025-01-18T20:59:00.180Z"}
{"level":"error","message":"Error en Transferencia de Clientes (Intento 1): Invalid object name 'CATELLI.CLIENTE'.","timestamp":"2025-01-19T19:30:01.053Z"}
{"level":"error","message":"Error en Transferencia de Clientes (Intento 2): Invalid object name 'CATELLI.CLIENTE'.","timestamp":"2025-01-19T19:30:04.075Z"}
{"level":"error","message":"Error en Transferencia de Clientes (Intento 3): Invalid object name 'CATELLI.CLIENTE'.","timestamp":"2025-01-19T19:30:07.096Z"}
{"level":"error","message":"Error en Transferencia de Clientes (ID: 1):","metadata":{"error":"Fallo en Transferencia de Clientes después de 3 intentos: Invalid object name 'CATELLI.CLIENTE'.","id":1,"name":"Transferencia de Clientes"},"timestamp":"2025-01-19T19:30:07.097Z"}
{"level":"error","message":"Error en las transferencias programadas: Fallo en Transferencia de Clientes: Fallo en Transferencia de Clientes después de 3 intentos: Invalid object name 'CATELLI.CLIENTE'.","timestamp":"2025-01-19T19:30:07.099Z"}
{"level":"error","message":"Error en Transferencia de Clientes (Intento 1): Invalid object name 'CATELLI.CLIENTE'.","timestamp":"2025-01-19T20:00:00.103Z"}
{"level":"error","message":"Error en Transferencia de Clientes (Intento 2): Invalid object name 'CATELLI.CLIENTE'.","timestamp":"2025-01-19T20:00:03.120Z"}
{"level":"error","message":"Error en Transferencia de Clientes (Intento 3): Invalid object name 'CATELLI.CLIENTE'.","timestamp":"2025-01-19T20:00:06.136Z"}
{"level":"error","message":"Error en Transferencia de Clientes (ID: 1):","metadata":{"error":"Fallo en Transferencia de Clientes después de 3 intentos: Invalid object name 'CATELLI.CLIENTE'.","id":1,"name":"Transferencia de Clientes"},"timestamp":"2025-01-19T20:00:06.136Z"}
{"level":"error","message":"Error en las transferencias programadas: Fallo en Transferencia de Clientes: Fallo en Transferencia de Clientes después de 3 intentos: Invalid object name 'CATELLI.CLIENTE'.","timestamp":"2025-01-19T20:00:06.137Z"}
